Workbook
Name VF: #REF!
Name REQUERIMIENTO: 'MOB-PEDG'!$K$4:$K$17
Name HERRAMIENTAS_V2: HERRAMIENTAS!$A$4:$AE$555
Name REQUERIMIENTO: HERRAMIENTAS!$AD$4:$AD$555
Name HERRAMIENTAS_V2: 'MOB-PEDG'!$A$4:$W$17
Name VF: 'MOB-PEDG'!$T$4:$T$17

Sheet EQUIPOS
B2: DESGLOSE DE EQUIPOS | N2: 👽 | S2: 🐈‍⬛
I3: =SUBTOTAL(9,I5:I478) -> 5147 | N3: PRIMERA VALIDACIÓN | S3: SEGUNDA VALIDACIÓN | W3: EXTRAÍDO DE PLAN DE COMPRAS
A4: N° | B4: REVISADO | C4: EN REQ | D4: RUBRO | E4: TIPO DE PRODUCTO | F4: CÓDIGO ENTIDAD | G4: CÓDIGO INTERNO (EETT) | H4: PRODUCTO | I4: CANT TOTAL | J4: CANT PLAN | K4: ¿IGUAL? | L4: TALLER | M4: EETT | N4: DETALLE | O4: MARCA | P4: MODELO | Q4: LINK DE REFERENCIA | R4: CET | S4: VALIDACIÓN FINAL | T4: MARCA | U4: MODELO | V4: FICHA TÉCNICA ACTUALIZADA | W4: TIPO DE VALIDACIÓN | X4: PROCEDENCIA | Y4: COMPRADOR | Z4: DESCRIPCIÓN SIDIGE | AB4: N° REQ | AC4: SKU | AD4: DESCRIPCIÓN | AE4: UNIDAD MEDIDA | AF4: CORTE FILTRO PEDAGOGÍA
A5: 1 | B5: TRUE | C5: TRUE | D5: BIEN | E5: EQUIPOS | F5: COM-106 | G5: COM-106 | H5: BALANZA 3KG | I5: =SUMIFS('Hoja 10'!$O:$O,'Hoja 10'!$F:$F,$G5) -> 4 | J5: =IFERROR(__xludf.DUMMYFUNCTION("VLOOKUP(G5,IMPORTRANGE(""https://docs.google.com/spreadsheets/d/12RxCea4e5ggM7QGn1XE3FbLQa_-QbCNdBi90OdPjRqg/edit?gid=1692403370#gid=1692403370"", ""'Plan de Compras'!D4:2432""), 8,0)"),4.0) -> 4 | K5: =IF( C5=TRUE, IF(I5=J5,"SI","NO"), "-") -> SI | L5: INDUSTRIA ALIMENTARIA | M5: 12 Taller_Industria_Alimentaria_Firmado.pdf | O5: =VLOOKUP($G5,'Hoja 10'!$F$4:$AA478, 19,0) -> OHAUS | P5: =VLOOKUP($G5,'Hoja 10'!$F$4:$AA478, 20,0) -> Valor™ 4000 | Q5: =VLOOKUP($G5,'Hoja 10'!$F$4:$AA478, 21,0) -> https://eu-es.ohaus.com/es-eu/products/balances-scales/bench-scales/valor-4000/v41xwe3t | R5: COM-106 BALANZA 3KG - CET | S5: TRUE | T5: =IFERROR(__xludf.DUMMYFUNCTION(" IF ( VLOOKUP($G5,IMPORTRANGE(""https://docs.google.com/spreadsheets/d/1Gpl6jkTg7sL4VDNimUm3S9Vi1i95esohXCF3wuKOE8c"", ""'CONSOLIDADO'!G5:AB""), 10, 0) <> 0, IFERROR(VLOOKUP($G5,IMPORTRANGE(""https://docs.google.com/spreadsheets/d/1Gpl6jkTg7sL4VDNimUm3S9"&"Vi1i95esohXCF3wuKOE8c"", ""'CONSOLIDADO'!G5:AB""), 17, 0), ""-""), """" )"),"OHAUS") -> OHAUS | U5: =IFERROR(__xludf.DUMMYFUNCTION(" IF ( VLOOKUP($G5,IMPORTRANGE(""https://docs.google.com/spreadsheets/d/1Gpl6jkTg7sL4VDNimUm3S9Vi1i95esohXCF3wuKOE8c"", ""'CONSOLIDADO'!G5:AB""), 10, 0) <> 0, IFERROR(VLOOKUP($G5,IMPORTRANGE(""https://docs.google.com/spreadsheets/d/1Gpl6jkTg7sL4VDNimUm3S9"&"Vi1i95esohXCF3wuKOE8c"", ""'CONSOLIDADO'!G5:AB""), 18, 0), ""-""), """" )"),"Valor™ 4000") -> Valor™ 4000 | V5: =IFERROR(__xludf.DUMMYFUNCTION(" IF ( VLOOKUP($G5,IMPORTRANGE(""https://docs.google.com/spreadsheets/d/1Gpl6jkTg7sL4VDNimUm3S9Vi1i95esohXCF3wuKOE8c"", ""'CONSOLIDADO'!G5:AB""), 10, 0) <> 0, IFERROR(VLOOKUP($G5,IMPORTRANGE(""https://docs.google.com/spreadsheets/d/1Gpl6jkTg7sL4VDNimUm3S9"&"Vi1i95esohXCF3wuKOE8c"", ""'CONSOLIDADO'!G5:AB""), 19, 0), ""-""), """" )"),"https://eu-es.ohaus.com/es-eu/products/balances-scales/bench-scales/valor-4000/v41xwe3t") -> https://eu-es.ohaus.com/es-eu/products/balances-scales/bench-scales/valor-4000/v41xwe3t | W5: =IFERROR(__xludf.DUMMYFUNCTION("IFERROR(VLOOKUP(G5,IMPORTRANGE(""https://docs.google.com/spreadsheets/d/12RxCea4e5ggM7QGn1XE3FbLQa_-QbCNdBi90OdPjRqg"", ""'Plan de Compras'!D4:Q""), 12, 0), ""NO ESTÁ EN REQ"")"),"Técnica") -> Técnica | X5: =IFERROR(__xludf.DUMMYFUNCTION("IFERROR(VLOOKUP(G5,IMPORTRANGE(""https://docs.google.com/spreadsheets/d/12RxCea4e5ggM7QGn1XE3FbLQa_-QbCNdBi90OdPjRqg"", ""'Plan de Compras'!D4:Q""), 13, 0), """")"),"INTERNACIONAL") -> INTERNACIONAL | Y5: =IFERROR(__xludf.DUMMYFUNCTION("IFERROR(VLOOKUP(G5,IMPORTRANGE(""https://docs.google.com/spreadsheets/d/12RxCea4e5ggM7QGn1XE3FbLQa_-QbCNdBi90OdPjRqg"", ""'Plan de Compras'!D4:Q""), 14, 0), """")"),"DIEGO ") -> DIEGO | Z5: =IFERROR(__xludf.DUMMYFUNCTION("IFERROR(VLOOKUP(G5,IMPORTRANGE(""https://docs.google.com/spreadsheets/d/12RxCea4e5ggM7QGn1XE3FbLQa_-QbCNdBi90OdPjRqg"", ""'Plan de Compras'!D4:Q""), 4, 0), """")"),"BALANZA 3KG") -> BALANZA 3KG | AA5: =IF(H5=Z5,"TRUE", "FALSE") -> TRUE | AB5: =IFERROR(__xludf.DUMMYFUNCTION("IFERROR(IF(OR(C5=TRUE,C5=""""),VLOOKUP(G5,IMPORTRANGE(""https://docs.google.com/spreadsheets/d/1z9A1Wq-kKrhRNG5RS2a2fKpY1wIhSVz2ZNmP2mOl588/edit?usp=sharing"",""REQ VF!E4:H""),4,0),""NO APLICA""),""GENERAR REQ"")"),"GENERAR REQ") -> GENERAR REQ | AC5: =IFERROR(__xludf.DUMMYFUNCTION("IFERROR(QUERY(IMPORTRANGE(""https://docs.google.com/spreadsheets/d/1z9A1Wq-kKrhRNG5RS2a2fKpY1wIhSVz2ZNmP2mOl588/edit?usp=sharing"",""REQ VF!E4:Q""),""SELECT Col10, Col11, Col12 WHERE Col1 = '""&G5&""'"",0),""NO APLICA"")"),"NO APLICA") -> NO APLICA
C6: TRUE | D6: ACCESORIO | E6: EQUIPOS | G6: COM-106.1 | H6: FUNDA IMPERMEABLE (1 UND) | I6: =$I$5 -> 4 | J6: =IFERROR(__xludf.DUMMYFUNCTION("VLOOKUP(G6,IMPORTRANGE(""https://docs.google.com/spreadsheets/d/12RxCea4e5ggM7QGn1XE3FbLQa_-QbCNdBi90OdPjRqg/edit?gid=1692403370#gid=1692403370"", ""'Plan de Compras'!D4:2432""), 8,0)"),4.0) -> 4 | K6: =IF( C6=TRUE, IF(I6=J6,"SI","NO"), "-") -> SI | N6: CON PROVEEDOR EXTERNO | P6: 256 x 124 x 288 mm | S6: TRUE | T6: GENÉRICO | U6: FUNDAS IMPERMEABLES 23 CM X 36 CM X 39 CM PARA BALANZA 3KG | W6: =IFERROR(__xludf.DUMMYFUNCTION("IFERROR(VLOOKUP(G6,IMPORTRANGE(""https://docs.google.com/spreadsheets/d/12RxCea4e5ggM7QGn1XE3FbLQa_-QbCNdBi90OdPjRqg"", ""'Plan de Compras'!D4:Q""), 12, 0), ""NO ESTÁ EN REQ"")"),"Técnica") -> Técnica | X6: =IFERROR(__xludf.DUMMYFUNCTION("IFERROR(VLOOKUP(G6,IMPORTRANGE(""https://docs.google.com/spreadsheets/d/12RxCea4e5ggM7QGn1XE3FbLQa_-QbCNdBi90OdPjRqg"", ""'Plan de Compras'!D4:Q""), 13, 0), """")"),"NACIONAL") -> NACIONAL | Y6: =IFERROR(__xludf.DUMMYFUNCTION("IFERROR(VLOOKUP(G6,IMPORTRANGE(""https://docs.google.com/spreadsheets/d/12RxCea4e5ggM7QGn1XE3FbLQa_-QbCNdBi90OdPjRqg"", ""'Plan de Compras'!D4:Q""), 14, 0), """")"),"ANGIE") -> ANGIE | Z6: =IFERROR(__xludf.DUMMYFUNCTION("IFERROR(VLOOKUP(G6,IMPORTRANGE(""https://docs.google.com/spreadsheets/d/12RxCea4e5ggM7QGn1XE3FbLQa_-QbCNdBi90OdPjRqg"", ""'Plan de Compras'!D4:Q""), 4, 0), """")"),"FUNDA IMPERMEABLE (1 UND)") -> FUNDA IMPERMEABLE (1 UND) | AA6: =IF(H6=Z6,"TRUE", "FALSE") -> TRUE | AB6: =IFERROR(__xludf.DUMMYFUNCTION("IFERROR(IF(OR(C6=TRUE,C6=""""),VLOOKUP(G6,IMPORTRANGE(""https://docs.google.com/spreadsheets/d/1z9A1Wq-kKrhRNG5RS2a2fKpY1wIhSVz2ZNmP2mOl588/edit?usp=sharing"",""REQ VF!E4:H""),4,0),""NO APLICA""),""GENERAR REQ"")"),"GENERAR REQ") -> GENERAR REQ | AC6: =IFERROR(__xludf.DUMMYFUNCTION("IFERROR(QUERY(IMPORTRANGE(""https://docs.google.com/spreadsheets/d/1z9A1Wq-kKrhRNG5RS2a2fKpY1wIhSVz2ZNmP2mOl588/edit?usp=sharing"",""REQ VF!E4:Q""),""SELECT Col10, Col11, Col12 WHERE Col1 = '""&G6&""'"",0),""NO APLICA"")"),"NO APLICA") -> NO APLICA
A7: 2 | B7: TRUE | C7: TRUE | D7: BIEN | E7: EQUIPOS | F7: COM-107 | G7: COM-107 | H7: BALANZA 40KG | I7: =SUMIFS('Hoja 10'!$O:$O,'Hoja 10'!$F:$F,$G7) -> 8 | J7: =IFERROR(__xludf.DUMMYFUNCTION("VLOOKUP(G7,IMPORTRANGE(""https://docs.google.com/spreadsheets/d/12RxCea4e5ggM7QGn1XE3FbLQa_-QbCNdBi90OdPjRqg/edit?gid=1692403370#gid=1692403370"", ""'Plan de Compras'!D4:2432""), 8,0)"),8.0) -> 8 | K7: =IF( C7=TRUE, IF(I7=J7,"SI","NO"), "-") -> SI | L7: INDUSTRIA ALIMENTARIA | M7: 12 Taller_Industria_Alimentaria_Firmado.pdf | O7: =VLOOKUP($G7,'Hoja 10'!$F$4:$AA478, 19,0) -> OPALUX | P7: =VLOOKUP($G7,'Hoja 10'!$F$4:$AA478, 20,0) -> OPALUX | Q7: =VLOOKUP($G7,'Hoja 10'!$F$4:$AA478, 21,0) -> https://opalux.lifestore.pe/producto/balanza-electronica-digital-de-mesa-40kgs-opalux-lcd-recargable-con-brazo-y-bateria-4v4ah-220v/ | R7: COM-107 BALANZA 40KG - CET | S7: TRUE | T7: =IFERROR(__xludf.DUMMYFUNCTION(" IF ( VLOOKUP($G7,IMPORTRANGE(""https://docs.google.com/spreadsheets/d/1Gpl6jkTg7sL4VDNimUm3S9Vi1i95esohXCF3wuKOE8c"", ""'CONSOLIDADO'!G5:AB""), 10, 0) <> 0, IFERROR(VLOOKUP($G7,IMPORTRANGE(""https://docs.google.com/spreadsheets/d/1Gpl6jkTg7sL4VDNimUm3S9"&"Vi1i95esohXCF3wuKOE8c"", ""'CONSOLIDADO'!G5:AB""), 17, 0), ""-""), """" )"),"Torrey") -> Torrey | U7: =IFERROR(__xludf.DUMMYFUNCTION(" IF ( VLOOKUP($G7,IMPORTRANGE(""https://docs.google.com/spreadsheets/d/1Gpl6jkTg7sL4VDNimUm3S9Vi1i95esohXCF3wuKOE8c"", ""'CONSOLIDADO'!G5:AB""), 10, 0) <> 0, IFERROR(VLOOKUP($G7,IMPORTRANGE(""https://docs.google.com/spreadsheets/d/1Gpl6jkTg7sL4VDNimUm3S9"&"Vi1i95esohXCF3wuKOE8c"", ""'CONSOLIDADO'!G5:AB""), 18, 0), ""-""), """" )"),"PCR – 40T") -> PCR – 40T | V7: =IFERROR(__xludf.DUMMYFUNCTION(" IF ( VLOOKUP($G7,IMPORTRANGE(""https://docs.google.com/spreadsheets/d/1Gpl6jkTg7sL4VDNimUm3S9Vi1i95esohXCF3wuKOE8c"", ""'CONSOLIDADO'!G5:AB""), 10, 0) <> 0, IFERROR(VLOOKUP($G7,IMPORTRANGE(""https://docs.google.com/spreadsheets/d/1Gpl6jkTg7sL4VDNimUm3S9"&"Vi1i95esohXCF3wuKOE8c"", ""'CONSOLIDADO'!G5:AB""), 19, 0), ""-""), """" )"),"https://opalux.lifestore.pe/producto/balanza-electronica-digital-de-mesa-40kgs-opalux-lcd-recargable-con-brazo-y-bateria-4v4ah-220v/") -> https://opalux.lifestore.pe/producto/balanza-electronica-digital-de-mesa-40kgs-opalux-lcd-recargable-con-brazo-y-bateria-4v4ah-220v/ | W7: =IFERROR(__xludf.DUMMYFUNCTION("IFERROR(VLOOKUP(G7,IMPORTRANGE(""https://docs.google.com/spreadsheets/d/12RxCea4e5ggM7QGn1XE3FbLQa_-QbCNdBi90OdPjRqg"", ""'Plan de Compras'!D4:Q""), 12, 0), ""NO ESTÁ EN REQ"")"),"Técnica") -> Técnica | X7: =IFERROR(__xludf.DUMMYFUNCTION("IFERROR(VLOOKUP(G7,IMPORTRANGE(""https://docs.google.com/spreadsheets/d/12RxCea4e5ggM7QGn1XE3FbLQa_-QbCNdBi90OdPjRqg"", ""'Plan de Compras'!D4:Q""), 13, 0), """")"),"NACIONAL") -> NACIONAL | Y7: =IFERROR(__xludf.DUMMYFUNCTION("IFERROR(VLOOKUP(G7,IMPORTRANGE(""https://docs.google.com/spreadsheets/d/12RxCea4e5ggM7QGn1XE3FbLQa_-QbCNdBi90OdPjRqg"", ""'Plan de Compras'!D4:Q""), 14, 0), """")"),"ANGIE") -> ANGIE | Z7: =IFERROR(__xludf.DUMMYFUNCTION("IFERROR(VLOOKUP(G7,IMPORTRANGE(""https://docs.google.com/spreadsheets/d/12RxCea4e5ggM7QGn1XE3FbLQa_-QbCNdBi90OdPjRqg"", ""'Plan de Compras'!D4:Q""), 4, 0), """")"),"BALANZA 40KG") -> BALANZA 40KG | AA7: =IF(H7=Z7,"TRUE", "FALSE") -> TRUE | AB7: =IFERROR(__xludf.DUMMYFUNCTION("IFERROR(IF(OR(C7=TRUE,C7=""""),VLOOKUP(G7,IMPORTRANGE(""https://docs.google.com/spreadsheets/d/1z9A1Wq-kKrhRNG5RS2a2fKpY1wIhSVz2ZNmP2mOl588/edit?usp=sharing"",""REQ VF!E4:H""),4,0),""NO APLICA""),""GENERAR REQ"")"),"GENERAR REQ") -> GENERAR REQ | AC7: =IFERROR(__xludf.DUMMYFUNCTION("IFERROR(QUERY(IMPORTRANGE(""https://docs.google.com/spreadsheets/d/1z9A1Wq-kKrhRNG5RS2a2fKpY1wIhSVz2ZNmP2mOl588/edit?usp=sharing"",""REQ VF!E4:Q""),""SELECT Col10, Col11, Col12 WHERE Col1 = '""&G7&""'"",0),""NO APLICA"")"),"NO APLICA") -> NO APLICA | AF7: C
C8: TRUE | D8: ACCESORIO | E8: EQUIPOS | F8: COM-107 | G8: COM-107.1 | H8: FUNDA IMPERMEABLE (1 UND) | I8: =I7 -> 8 | J8: =IFERROR(__xludf.DUMMYFUNCTION("VLOOKUP(G8,IMPORTRANGE(""https://docs.google.com/spreadsheets/d/12RxCea4e5ggM7QGn1XE3FbLQa_-QbCNdBi90OdPjRqg/edit?gid=1692403370#gid=1692403370"", ""'Plan de Compras'!D4:2432""), 8,0)"),8.0) -> 8 | K8: =IF( C8=TRUE, IF(I8=J8,"SI","NO"), "-") -> SI | N8: CON PROVEEDOR EXTERNO | P8: 342 x 330 x 475 mm | S8: TRUE | T8: GENERICO | U8: FUNDAS IMPERMEABLES 48 CM X 42 CM X 40 CM PARA BALANZA 40KG | W8: =IFERROR(__xludf.DUMMYFUNCTION("IFERROR(VLOOKUP(G8,IMPORTRANGE(""https://docs.google.com/spreadsheets/d/12RxCea4e5ggM7QGn1XE3FbLQa_-QbCNdBi90OdPjRqg"", ""'Plan de Compras'!D4:Q""), 12, 0), ""NO ESTÁ EN REQ"")"),"Simple") -> Simple | X8: =IFERROR(__xludf.DUMMYFUNCTION("IFERROR(VLOOKUP(G8,IMPORTRANGE(""https://docs.google.com/spreadsheets/d/12RxCea4e5ggM7QGn1XE3FbLQa_-QbCNdBi90OdPjRqg"", ""'Plan de Compras'!D4:Q""), 13, 0), """")"),"NACIONAL") -> NACIONAL | Y8: =IFERROR(__xludf.DUMMYFUNCTION("IFERROR(VLOOKUP(G8,IMPORTRANGE(""https://docs.google.com/spreadsheets/d/12RxCea4e5ggM7QGn1XE3FbLQa_-QbCNdBi90OdPjRqg"", ""'Plan de Compras'!D4:Q""), 14, 0), """")"),"ANGIE") -> ANGIE | Z8: =IFERROR(__xludf.DUMMYFUNCTION("IFERROR(VLOOKUP(G8,IMPORTRANGE(""https://docs.google.com/spreadsheets/d/12RxCea4e5ggM7QGn1XE3FbLQa_-QbCNdBi90OdPjRqg"", ""'Plan de Compras'!D4:Q""), 4, 0), """")"),"FUNDA IMPERMEABLE (1 UND)") -> FUNDA IMPERMEABLE (1 UND) | AA8: =IF(H8=Z8,"TRUE", "FALSE") -> TRUE | AB8: =IFERROR(__xludf.DUMMYFUNCTION("IFERROR(IF(OR(C8=TRUE,C8=""""),VLOOKUP(G8,IMPORTRANGE(""https://docs.google.com/spreadsheets/d/1z9A1Wq-kKrhRNG5RS2a2fKpY1wIhSVz2ZNmP2mOl588/edit?usp=sharing"",""REQ VF!E4:H""),4,0),""NO APLICA""),""GENERAR REQ"")"),"GENERAR REQ") -> GENERAR REQ | AC8: =IFERROR(__xludf.DUMMYFUNCTION("IFERROR(QUERY(IMPORTRANGE(""https://docs.google.com/spreadsheets/d/1z9A1Wq-kKrhRNG5RS2a2fKpY1wIhSVz2ZNmP2mOl588/edit?usp=sharing"",""REQ VF!E4:Q""),""SELECT Col10, Col11, Col12 WHERE Col1 = '""&G8&""'"",0),""NO APLICA"")"),"NO APLICA") -> NO APLICA
A9: 3 | B9: TRUE | C9: TRUE | D9: BIEN | E9: EQUIPOS | F9: COM-108 | G9: COM-108 | H9: BALANZA 5KG | I9: =SUMIFS('Hoja 10'!$O:$O,'Hoja 10'!$F:$F,$G9) -> 4 | J9: =IFERROR(__xludf.DUMMYFUNCTION("VLOOKUP(G9,IMPORTRANGE(""https://docs.google.com/spreadsheets/d/12RxCea4e5ggM7QGn1XE3FbLQa_-QbCNdBi90OdPjRqg/edit?gid=1692403370#gid=1692403370"", ""'Plan de Compras'!D4:2432""), 8,0)"),4.0) -> 4 | K9: =IF( C9=TRUE, IF(I9=J9,"SI","NO"), "-") -> SI | L9: INDUSTRIA ALIMENTARIA | M9: 12 Taller_Industria_Alimentaria_Firmado.pdf | O9: =VLOOKUP($G9,'Hoja 10'!$F$4:$AA478, 19,0) -> Precisur | P9: =VLOOKUP($G9,'Hoja 10'!$F$4:$AA478, 20,0) -> BRD | Q9: =VLOOKUP($G9,'Hoja 10'!$F$4:$AA478, 21,0) -> https://lacasadelabalanzaperu.com/producto/balanza-gramera-brd-de-5-kilos/?srsltid=AfmBOoqESFO4ybWNXMKI8ni8CSFROATsEcEQxFdxgt7due_hwv2yVsh2 | R9: COM-108 BALANZA 5KG - CET | S9: TRUE | T9: =IFERROR(__xludf.DUMMYFUNCTION(" IF ( VLOOKUP($G9,IMPORTRANGE(""https://docs.google.com/spreadsheets/d/1Gpl6jkTg7sL4VDNimUm3S9Vi1i95esohXCF3wuKOE8c"", ""'CONSOLIDADO'!G5:AB""), 10, 0) <> 0, IFERROR(VLOOKUP($G9,IMPORTRANGE(""https://docs.google.com/spreadsheets/d/1Gpl6jkTg7sL4VDNimUm3S9"&"Vi1i95esohXCF3wuKOE8c"", ""'CONSOLIDADO'!G5:AB""), 17, 0), ""-""), """" )"),"Precisur") -> Precisur | U9: =IFERROR(__xludf.DUMMYFUNCTION(" IF ( VLOOKUP($G9,IMPORTRANGE(""https://docs.google.com/spreadsheets/d/1Gpl6jkTg7sL4VDNimUm3S9Vi1i95esohXCF3wuKOE8c"", ""'CONSOLIDADO'!G5:AB""), 10, 0) <> 0, IFERROR(VLOOKUP($G9,IMPORTRANGE(""https://docs.google.com/spreadsheets/d/1Gpl6jkTg7sL4VDNimUm3S9"&"Vi1i95esohXCF3wuKOE8c"", ""'CONSOLIDADO'!G5:AB""), 18, 0), ""-""), """" )"),"BRD") -> BRD | V9: =IFERROR(__xludf.DUMMYFUNCTION(" IF ( VLOOKUP($G9,IMPORTRANGE(""https://docs.google.com/spreadsheets/d/1Gpl6jkTg7sL4VDNimUm3S9Vi1i95esohXCF3wuKOE8c"", ""'CONSOLIDADO'!G5:AB""), 10, 0) <> 0, IFERROR(VLOOKUP($G9,IMPORTRANGE(""https://docs.google.com/spreadsheets/d/1Gpl6jkTg7sL4VDNimUm3S9"&"Vi1i95esohXCF3wuKOE8c"", ""'CONSOLIDADO'!G5:AB""), 19, 0), ""-""), """" )"),"https://balanzasprecisur.com/balanzas-grameras/balanza-gramera-precisur-brd-de-5-kilos/?srsltid=AfmBOoonqZsXOjmBofRnpTJMaafb52Afo-ssPdM32gdpQef_duHaKTSH") -> https://balanzasprecisur.com/balanzas-grameras/balanza-gramera-precisur-brd-de-5-kilos/?srsltid=AfmBOoonqZsXOjmBofRnpTJMaafb52Afo-ssPdM32gdpQef_duHaKTSH | W9: =IFERROR(__xludf.DUMMYFUNCTION("IFERROR(VLOOKUP(G9,IMPORTRANGE(""https://docs.google.com/spreadsheets/d/12RxCea4e5ggM7QGn1XE3FbLQa_-QbCNdBi90OdPjRqg"", ""'Plan de Compras'!D4:Q""), 12, 0), ""NO ESTÁ EN REQ"")"),"Técnica") -> Técnica | X9: =IFERROR(__xludf.DUMMYFUNCTION("IFERROR(VLOOKUP(G9,IMPORTRANGE(""https://docs.google.com/spreadsheets/d/12RxCea4e5ggM7QGn1XE3FbLQa_-QbCNdBi90OdPjRqg"", ""'Plan de Compras'!D4:Q""), 13, 0), """")"),"NACIONAL") -> NACIONAL | Y9: =IFERROR(__xludf.DUMMYFUNCTION("IFERROR(VLOOKUP(G9,IMPORTRANGE(""https://docs.google.com/spreadsheets/d/12RxCea4e5ggM7QGn1XE3FbLQa_-QbCNdBi90OdPjRqg"", ""'Plan de Compras'!D4:Q""), 14, 0), """")"),"ANGIE") -> ANGIE | Z9: =IFERROR(__xludf.DUMMYFUNCTION("IFERROR(VLOOKUP(G9,IMPORTRANGE(""https://docs.google.com/spreadsheets/d/12RxCea4e5ggM7QGn1XE3FbLQa_-QbCNdBi90OdPjRqg"", ""'Plan de Compras'!D4:Q""), 4, 0), """")"),"BALANZA 5KG") -> BALANZA 5KG | AA9: =IF(H9=Z9,"TRUE", "FALSE") -> TRUE | AB9: =IFERROR(__xludf.DUMMYFUNCTION("IFERROR(IF(OR(C9=TRUE,C9=""""),VLOOKUP(G9,IMPORTRANGE(""https://docs.google.com/spreadsheets/d/1z9A1Wq-kKrhRNG5RS2a2fKpY1wIhSVz2ZNmP2mOl588/edit?usp=sharing"",""REQ VF!E4:H""),4,0),""NO APLICA""),""GENERAR REQ"")"),"GENERAR REQ") -> GENERAR REQ | AC9: =IFERROR(__xludf.DUMMYFUNCTION("IFERROR(QUERY(IMPORTRANGE(""https://docs.google.com/spreadsheets/d/1z9A1Wq-kKrhRNG5RS2a2fKpY1wIhSVz2ZNmP2mOl588/edit?usp=sharing"",""REQ VF!E4:Q""),""SELECT Col10, Col11, Col12 WHERE Col1 = '""&G9&""'"",0),""NO APLICA"")"),"NO APLICA") -> NO APLICA | AF9: C
C10: TRUE | D10: ACCESORIO | E10: EQUIPOS | F10: COM-108 | G10: COM-108.1 | H10: CARGADOR DE PILAS RECARGABLES (1 UND) | I10: =$I$9 -> 4 | J10: =IFERROR(__xludf.DUMMYFUNCTION("VLOOKUP(G10,IMPORTRANGE(""https://docs.google.com/spreadsheets/d/12RxCea4e5ggM7QGn1XE3FbLQa_-QbCNdBi90OdPjRqg/edit?gid=1692403370#gid=1692403370"", ""'Plan de Compras'!D4:2432""), 8,0)"),4.0) -> 4 | K10: =IF( C10=TRUE, IF(I10=J10,"SI","NO"), "-") -> SI | N10: CARGADOR DE PILAS AA/AAA | Q10: https://www.coolbox.pe/cargador-de-pilas-radioshack-aaaaa-2-pilas-aa-2309221/p | S10: TRUE | T10: Beston | U10: HD-4883 | W10: =IFERROR(__xludf.DUMMYFUNCTION("IFERROR(VLOOKUP(G10,IMPORTRANGE(""https://docs.google.com/spreadsheets/d/12RxCea4e5ggM7QGn1XE3FbLQa_-QbCNdBi90OdPjRqg"", ""'Plan de Compras'!D4:Q""), 12, 0), ""NO ESTÁ EN REQ"")"),"Técnica") -> Técnica | X10: =IFERROR(__xludf.DUMMYFUNCTION("IFERROR(VLOOKUP(G10,IMPORTRANGE(""https://docs.google.com/spreadsheets/d/12RxCea4e5ggM7QGn1XE3FbLQa_-QbCNdBi90OdPjRqg"", ""'Plan de Compras'!D4:Q""), 13, 0), """")"),"NACIONAL") -> NACIONAL | Y10: =IFERROR(__xludf.DUMMYFUNCTION("IFERROR(VLOOKUP(G10,IMPORTRANGE(""https://docs.google.com/spreadsheets/d/12RxCea4e5ggM7QGn1XE3FbLQa_-QbCNdBi90OdPjRqg"", ""'Plan de Compras'!D4:Q""), 14, 0), """")"),"ALFIO") -> ALFIO | Z10: =IFERROR(__xludf.DUMMYFUNCTION("IFERROR(VLOOKUP(G10,IMPORTRANGE(""https://docs.google.com/spreadsheets/d/12RxCea4e5ggM7QGn1XE3FbLQa_-QbCNdBi90OdPjRqg"", ""'Plan de Compras'!D4:Q""), 4, 0), """")"),"CARGADOR DE PILAS RECARGABLES (1 UND)") -> CARGADOR DE PILAS RECARGABLES (1 UND) | AA10: =IF(H10=Z10,"TRUE", "FALSE") -> TRUE | AB10: =IFERROR(__xludf.DUMMYFUNCTION("IFERROR(IF(OR(C10=TRUE,C10=""""),VLOOKUP(G10,IMPORTRANGE(""https://docs.google.com/spreadsheets/d/1z9A1Wq-kKrhRNG5RS2a2fKpY1wIhSVz2ZNmP2mOl588/edit?usp=sharing"",""REQ VF!E4:H""),4,0),""NO APLICA""),""GENERAR REQ"")"),"GENERAR REQ") -> GENERAR REQ | AC10: =IFERROR(__xludf.DUMMYFUNCTION("IFERROR(QUERY(IMPORTRANGE(""https://docs.google.com/spreadsheets/d/1z9A1Wq-kKrhRNG5RS2a2fKpY1wIhSVz2ZNmP2mOl588/edit?usp=sharing"",""REQ VF!E4:Q""),""SELECT Col10, Col11, Col12 WHERE Col1 = '""&G10&""'"",0),""NO APLICA"")"),"NO APLICA") -> NO APLICA
C11: TRUE | D11: ACCESORIO | E11: EQUIPOS | F11: COM-108 | G11: COM-108.2 | H11: PACK DE 2 PILAS RECARGABLES (1 UND) | I11: =$I$9 -> 4 | J11: =IFERROR(__xludf.DUMMYFUNCTION("VLOOKUP(G11,IMPORTRANGE(""https://docs.google.com/spreadsheets/d/12RxCea4e5ggM7QGn1XE3FbLQa_-QbCNdBi90OdPjRqg/edit?gid=1692403370#gid=1692403370"", ""'Plan de Compras'!D4:2432""), 8,0)"),4.0) -> 4 | K11: =IF( C11=TRUE, IF(I11=J11,"SI","NO"), "-") -> SI | N11: PILAS RECARGABLES AAA 800 MAH | Q11: https://www.coolbox.pe/pila-recargable-energizer-aaa-x2-220390/p | S11: TRUE | T11: Camelion | U11: 1001503407 | W11: =IFERROR(__xludf.DUMMYFUNCTION("IFERROR(VLOOKUP(G11,IMPORTRANGE(""https://docs.google.com/spreadsheets/d/12RxCea4e5ggM7QGn1XE3FbLQa_-QbCNdBi90OdPjRqg"", ""'Plan de Compras'!D4:Q""), 12, 0), ""NO ESTÁ EN REQ"")"),"Técnica") -> Técnica | X11: =IFERROR(__xludf.DUMMYFUNCTION("IFERROR(VLOOKUP(G11,IMPORTRANGE(""https://docs.google.com/spreadsheets/d/12RxCea4e5ggM7QGn1XE3FbLQa_-QbCNdBi90OdPjRqg"", ""'Plan de Compras'!D4:Q""), 13, 0), """")"),"NACIONAL") -> NACIONAL | Y11: =IFERROR(__xludf.DUMMYFUNCTION("IFERROR(VLOOKUP(G11,IMPORTRANGE(""https://docs.google.com/spreadsheets/d/12RxCea4e5ggM7QGn1XE3FbLQa_-QbCNdBi90OdPjRqg"", ""'Plan de Compras'!D4:Q""), 14, 0), """")"),"ALFIO") -> ALFIO | Z11: =IFERROR(__xludf.DUMMYFUNCTION("IFERROR(VLOOKUP(G11,IMPORTRANGE(""https://docs.google.com/spreadsheets/d/12RxCea4e5ggM7QGn1XE3FbLQa_-QbCNdBi90OdPjRqg"", ""'Plan de Compras'!D4:Q""), 4, 0), """")"),"PACK DE 2 PILAS RECARGABLES (1 UND)") -> PACK DE 2 PILAS RECARGABLES (1 UND) | AA11: =IF(H11=Z11,"TRUE", "FALSE") -> TRUE | AB11: =IFERROR(__xludf.DUMMYFUNCTION("IFERROR(IF(OR(C11=TRUE,C11=""""),VLOOKUP(G11,IMPORTRANGE(""https://docs.google.com/spreadsheets/d/1z9A1Wq-kKrhRNG5RS2a2fKpY1wIhSVz2ZNmP2mOl588/edit?usp=sharing"",""REQ VF!E4:H""),4,0),""NO APLICA""),""GENERAR REQ"")"),"GENERAR REQ") -> GENERAR REQ | AC11: =IFERROR(__xludf.DUMMYFUNCTION("IFERROR(QUERY(IMPORTRANGE(""https://docs.google.com/spreadsheets/d/1z9A1Wq-kKrhRNG5RS2a2fKpY1wIhSVz2ZNmP2mOl588/edit?usp=sharing"",""REQ VF!E4:Q""),""SELECT Col10, Col11, Col12 WHERE Col1 = '""&G11&""'"",0),""NO APLICA"")"),"NO APLICA") -> NO APLICA
C12: TRUE | D12: ACCESORIO | E12: EQUIPOS | F12: COM-108 | G12: COM-108.3 | H12: FUNDA IMPERMEABLE (1 UND) | I12: =$I$9 -> 4 | J12: =IFERROR(__xludf.DUMMYFUNCTION("VLOOKUP(G12,IMPORTRANGE(""https://docs.google.com/spreadsheets/d/12RxCea4e5ggM7QGn1XE3FbLQa_-QbCNdBi90OdPjRqg/edit?gid=1692403370#gid=1692403370"", ""'Plan de Compras'!D4:2432""), 8,0)"),4.0) -> 4 | K12: =IF( C12=TRUE, IF(I12=J12,"SI","NO"), "-") -> SI | N12: CON PROVEEDOR EXTERNO | P12: 195 x 180 x 50 mm | S12: TRUE | T12: GENÉRICO | U12: FUNDAS IMPERMEABLES 22 CM X 23 CM X 9 CM PARA BALANZA 5KG | W12: =IFERROR(__xludf.DUMMYFUNCTION("IFERROR(VLOOKUP(G12,IMPORTRANGE(""https://docs.google.com/spreadsheets/d/12RxCea4e5ggM7QGn1XE3FbLQa_-QbCNdBi90OdPjRqg"", ""'Plan de Compras'!D4:Q""), 12, 0), ""NO ESTÁ EN REQ"")"),"Simple") -> Simple | X12: =IFERROR(__xludf.DUMMYFUNCTION("IFERROR(VLOOKUP(G12,IMPORTRANGE(""https://docs.google.com/spreadsheets/d/12RxCea4e5ggM7QGn1XE3FbLQa_-QbCNdBi90OdPjRqg"", ""'Plan de Compras'!D4:Q""), 13, 0), """")"),"NACIONAL") -> NACIONAL | Y12: =IFERROR(__xludf.DUMMYFUNCTION("IFERROR(VLOOKUP(G12,IMPORTRANGE(""https://docs.google.com/spreadsheets/d/12RxCea4e5ggM7QGn1XE3FbLQa_-QbCNdBi90OdPjRqg"", ""'Plan de Compras'!D4:Q""), 14, 0), """")"),"ANGIE") -> ANGIE | Z12: =IFERROR(__xludf.DUMMYFUNCTION("IFERROR(VLOOKUP(G12,IMPORTRANGE(""https://docs.google.com/spreadsheets/d/12RxCea4e5ggM7QGn1XE3FbLQa_-QbCNdBi90OdPjRqg"", ""'Plan de Compras'!D4:Q""), 4, 0), """")"),"FUNDA IMPERMEABLE (1 UND)") -> FUNDA IMPERMEABLE (1 UND) | AA12: =IF(H12=Z12,"TRUE", "FALSE") -> TRUE | AB12: =IFERROR(__xludf.DUMMYFUNCTION("IFERROR(IF(OR(C12=TRUE,C12=""""),VLOOKUP(G12,IMPORTRANGE(""https://docs.google.com/spreadsheets/d/1z9A1Wq-kKrhRNG5RS2a2fKpY1wIhSVz2ZNmP2mOl588/edit?usp=sharing"",""REQ VF!E4:H""),4,0),""NO APLICA""),""GENERAR REQ"")"),"GENERAR REQ") -> GENERAR REQ | AC12: =IFERROR(__xludf.DUMMYFUNCTION("IFERROR(QUERY(IMPORTRANGE(""https://docs.google.com/spreadsheets/d/1z9A1Wq-kKrhRNG5RS2a2fKpY1wIhSVz2ZNmP2mOl588/edit?usp=sharing"",""REQ VF!E4:Q""),""SELECT Col10, Col11, Col12 WHERE Col1 = '""&G12&""'"",0),""NO APLICA"")"),"NO APLICA") -> NO APLICA
A13: 4 | B13: TRUE | C13: TRUE | D13: BIEN | E13: EQUIPOS | F13: COM-110 | G13: COM-110-X | H13: BALANZA DIGITAL | I13: =SUMIFS('Hoja 10'!$O:$O,'Hoja 10'!$F:$F,$G13) -> 1 | J13: =IFERROR(__xludf.DUMMYFUNCTION("VLOOKUP(G13,IMPORTRANGE(""https://docs.google.com/spreadsheets/d/12RxCea4e5ggM7QGn1XE3FbLQa_-QbCNdBi90OdPjRqg/edit?gid=1692403370#gid=1692403370"", ""'Plan de Compras'!D4:2432""), 8,0)"),1.0) -> 1 | K13: =IF( C13=TRUE, IF(I13=J13,"SI","NO"), "-") -> SI | L13: COCINA Y REPOSTERÍA | M13: 5 Taller_Cocina y Respostería_Firmado.pdf | O13: =VLOOKUP($G13,'Hoja 10'!$F$4:$AA478, 19,0) -> Torrey | P13: =VLOOKUP($G13,'Hoja 10'!$F$4:$AA478, 20,0) -> PCR – 40T | Q13: =VLOOKUP($G13,'Hoja 10'!$F$4:$AA478, 21,0) -> https://balanzasprecisur.com/balanzas-comerciales/balanza-torrey-pcr-40t-de-40-kilos/ | R13: COM-110-X BALANZA DIGITAL - CET | S13: TRUE | T13: =IFERROR(__xludf.DUMMYFUNCTION(" IF ( VLOOKUP($G13,IMPORTRANGE(""https://docs.google.com/spreadsheets/d/1Gpl6jkTg7sL4VDNimUm3S9Vi1i95esohXCF3wuKOE8c"", ""'CONSOLIDADO'!G5:AB""), 10, 0) <> 0, IFERROR(VLOOKUP($G13,IMPORTRANGE(""https://docs.google.com/spreadsheets/d/1Gpl6jkTg7sL4VDNimUm3"&"S9Vi1i95esohXCF3wuKOE8c"", ""'CONSOLIDADO'!G5:AB""), 17, 0), ""-""), """" )"),"Torrey") -> Torrey | U13: =IFERROR(__xludf.DUMMYFUNCTION(" IF ( VLOOKUP($G13,IMPORTRANGE(""https://docs.google.com/spreadsheets/d/1Gpl6jkTg7sL4VDNimUm3S9Vi1i95esohXCF3wuKOE8c"", ""'CONSOLIDADO'!G5:AB""), 10, 0) <> 0, IFERROR(VLOOKUP($G13,IMPORTRANGE(""https://docs.google.com/spreadsheets/d/1Gpl6jkTg7sL4VDNimUm3"&"S9Vi1i95esohXCF3wuKOE8c"", ""'CONSOLIDADO'!G5:AB""), 18, 0), ""-""), """" )"),"PCR – 40T") -> PCR – 40T | V13: =IFERROR(__xludf.DUMMYFUNCTION(" IF ( VLOOKUP($G13,IMPORTRANGE(""https://docs.google.com/spreadsheets/d/1Gpl6jkTg7sL4VDNimUm3S9Vi1i95esohXCF3wuKOE8c"", ""'CONSOLIDADO'!G5:AB""), 10, 0) <> 0, IFERROR(VLOOKUP($G13,IMPORTRANGE(""https://docs.google.com/spreadsheets/d/1Gpl6jkTg7sL4VDNimUm3"&"S9Vi1i95esohXCF3wuKOE8c"", ""'CONSOLIDADO'!G5:AB""), 19, 0), ""-""), """" )"),"https://balanzasprecisur.com/balanzas-comerciales/balanza-torrey-pcr-40t-de-40-kilos/") -> https://balanzasprecisur.com/balanzas-comerciales/balanza-torrey-pcr-40t-de-40-kilos/ | W13: =IFERROR(__xludf.DUMMYFUNCTION("IFERROR(VLOOKUP(G13,IMPORTRANGE(""https://docs.google.com/spreadsheets/d/12RxCea4e5ggM7QGn1XE3FbLQa_-QbCNdBi90OdPjRqg"", ""'Plan de Compras'!D4:Q""), 12, 0), ""NO ESTÁ EN REQ"")"),"Técnica") -> Técnica | X13: =IFERROR(__xludf.DUMMYFUNCTION("IFERROR(VLOOKUP(G13,IMPORTRANGE(""https://docs.google.com/spreadsheets/d/12RxCea4e5ggM7QGn1XE3FbLQa_-QbCNdBi90OdPjRqg"", ""'Plan de Compras'!D4:Q""), 13, 0), """")"),"NACIONAL") -> NACIONAL | Y13: =IFERROR(__xludf.DUMMYFUNCTION("IFERROR(VLOOKUP(G13,IMPORTRANGE(""https://docs.google.com/spreadsheets/d/12RxCea4e5ggM7QGn1XE3FbLQa_-QbCNdBi90OdPjRqg"", ""'Plan de Compras'!D4:Q""), 14, 0), """")"),"ANGIE") -> ANGIE | Z13: =IFERROR(__xludf.DUMMYFUNCTION("IFERROR(VLOOKUP(G13,IMPORTRANGE(""https://docs.google.com/spreadsheets/d/12RxCea4e5ggM7QGn1XE3FbLQa_-QbCNdBi90OdPjRqg"", ""'Plan de Compras'!D4:Q""), 4, 0), """")"),"BALANZA DIGITAL") -> BALANZA DIGITAL | AA13: =IF(H13=Z13,"TRUE", "FALSE") -> TRUE | AB13: =IFERROR(__xludf.DUMMYFUNCTION("IFERROR(IF(OR(C13=TRUE,C13=""""),VLOOKUP(G13,IMPORTRANGE(""https://docs.google.com/spreadsheets/d/1z9A1Wq-kKrhRNG5RS2a2fKpY1wIhSVz2ZNmP2mOl588/edit?usp=sharing"",""REQ VF!E4:H""),4,0),""NO APLICA""),""GENERAR REQ"")"),"GENERAR REQ") -> GENERAR REQ | AC13: =IFERROR(__xludf.DUMMYFUNCTION("IFERROR(QUERY(IMPORTRANGE(""https://docs.google.com/spreadsheets/d/1z9A1Wq-kKrhRNG5RS2a2fKpY1wIhSVz2ZNmP2mOl588/edit?usp=sharing"",""REQ VF!E4:Q""),""SELECT Col10, Col11, Col12 WHERE Col1 = '""&G13&""'"",0),""NO APLICA"")"),"NO APLICA") -> NO APLICA | AF13: C
C14: TRUE | D14: ACCESORIO | E14: EQUIPOS | F14: COM-110 | G14: COM-110-X.1 | H14: FUNDA IMPERMEABLE (1 UND) | I14: =$I$13 -> 1 | J14: =IFERROR(__xludf.DUMMYFUNCTION("VLOOKUP(G14,IMPORTRANGE(""https://docs.google.com/spreadsheets/d/12RxCea4e5ggM7QGn1XE3FbLQa_-QbCNdBi90OdPjRqg/edit?gid=1692403370#gid=1692403370"", ""'Plan de Compras'!D4:2432""), 8,0)"),1.0) -> 1 | K14: =IF( C14=TRUE, IF(I14=J14,"SI","NO"), "-") -> SI | N14: CON PROVEEDOR EXTERNO | P14: 360 x 435 x 365 mm | S14: TRUE | T14: GENERICO | U14: FUNDAS IMPERMEABLES 48 CM X 42 CM X 40 CM PARA BALANZA DIGITAL | W14: =IFERROR(__xludf.DUMMYFUNCTION("IFERROR(VLOOKUP(G14,IMPORTRANGE(""https://docs.google.com/spreadsheets/d/12RxCea4e5ggM7QGn1XE3FbLQa_-QbCNdBi90OdPjRqg"", ""'Plan de Compras'!D4:Q""), 12, 0), ""NO ESTÁ EN REQ"")"),"Simple") -> Simple | X14: =IFERROR(__xludf.DUMMYFUNCTION("IFERROR(VLOOKUP(G14,IMPORTRANGE(""https://docs.google.com/spreadsheets/d/12RxCea4e5ggM7QGn1XE3FbLQa_-QbCNdBi90OdPjRqg"", ""'Plan de Compras'!D4:Q""), 13, 0), """")"),"NACIONAL") -> NACIONAL | Y14: =IFERROR(__xludf.DUMMYFUNCTION("IFERROR(VLOOKUP(G14,IMPORTRANGE(""https://docs.google.com/spreadsheets/d/12RxCea4e5ggM7QGn1XE3FbLQa_-QbCNdBi90OdPjRqg"", ""'Plan de Compras'!D4:Q""), 14, 0), """")"),"ANGIE") -> ANGIE | Z14: =IFERROR(__xludf.DUMMYFUNCTION("IFERROR(VLOOKUP(G14,IMPORTRANGE(""https://docs.google.com/spreadsheets/d/12RxCea4e5ggM7QGn1XE3FbLQa_-QbCNdBi90OdPjRqg"", ""'Plan de Compras'!D4:Q""), 4, 0), """")"),"FUNDA IMPERMEABLE (1 UND)") -> FUNDA IMPERMEABLE (1 UND) | AA14: =IF(H14=Z14,"TRUE", "FALSE") -> TRUE | AB14: =IFERROR(__xludf.DUMMYFUNCTION("IFERROR(IF(OR(C14=TRUE,C14=""""),VLOOKUP(G14,IMPORTRANGE(""https://docs.google.com/spreadsheets/d/1z9A1Wq-kKrhRNG5RS2a2fKpY1wIhSVz2ZNmP2mOl588/edit?usp=sharing"",""REQ VF!E4:H""),4,0),""NO APLICA""),""GENERAR REQ"")"),"GENERAR REQ") -> GENERAR REQ | AC14: =IFERROR(__xludf.DUMMYFUNCTION("IFERROR(QUERY(IMPORTRANGE(""https://docs.google.com/spreadsheets/d/1z9A1Wq-kKrhRNG5RS2a2fKpY1wIhSVz2ZNmP2mOl588/edit?usp=sharing"",""REQ VF!E4:Q""),""SELECT Col10, Col11, Col12 WHERE Col1 = '""&G14&""'"",0),""NO APLICA"")"),"NO APLICA") -> NO APLICA
A15: 5 | B15: TRUE | C15: TRUE | D15: BIEN | E15: EQUIPOS | F15: COM-110 | G15: COM-110-Y | H15: BALANZA DIGITAL | I15: =SUMIFS('Hoja 10'!$O:$O,'Hoja 10'!$F:$F,$G15) -> 8 | J15: =IFERROR(__xludf.DUMMYFUNCTION("VLOOKUP(G15,IMPORTRANGE(""https://docs.google.com/spreadsheets/d/12RxCea4e5ggM7QGn1XE3FbLQa_-QbCNdBi90OdPjRqg/edit?gid=1692403370#gid=1692403370"", ""'Plan de Compras'!D4:2432""), 8,0)"),8.0) -> 8 | K15: =IF( C15=TRUE, IF(I15=J15,"SI","NO"), "-") -> SI | L15: INDUSTRIA ALIMENTARIA | M15: 12 Taller_Industria_Alimentaria_Firmado.pdf | O15: =VLOOKUP($G15,'Hoja 10'!$F$4:$AA478, 19,0) -> Torrey | P15: =VLOOKUP($G15,'Hoja 10'!$F$4:$AA478, 20,0) -> PCR – 40T | Q15: =VLOOKUP($G15,'Hoja 10'!$F$4:$AA478, 21,0) -> https://balanzasprecisur.com/balanzas-comerciales/balanza-torrey-pcr-40t-de-40-kilos/ | R15: COM-110-Y BALANZA DIGITAL - CET | S15: TRUE | T15: =IFERROR(__xludf.DUMMYFUNCTION(" IF ( VLOOKUP($G15,IMPORTRANGE(""https://docs.google.com/spreadsheets/d/1Gpl6jkTg7sL4VDNimUm3S9Vi1i95esohXCF3wuKOE8c"", ""'CONSOLIDADO'!G5:AB""), 10, 0) <> 0, IFERROR(VLOOKUP($G15,IMPORTRANGE(""https://docs.google.com/spreadsheets/d/1Gpl6jkTg7sL4VDNimUm3"&"S9Vi1i95esohXCF3wuKOE8c"", ""'CONSOLIDADO'!G5:AB""), 17, 0), ""-""), """" )"),"Torrey") -> Torrey | U15: =IFERROR(__xludf.DUMMYFUNCTION(" IF ( VLOOKUP($G15,IMPORTRANGE(""https://docs.google.com/spreadsheets/d/1Gpl6jkTg7sL4VDNimUm3S9Vi1i95esohXCF3wuKOE8c"", ""'CONSOLIDADO'!G5:AB""), 10, 0) <> 0, IFERROR(VLOOKUP($G15,IMPORTRANGE(""https://docs.google.com/spreadsheets/d/1Gpl6jkTg7sL4VDNimUm3"&"S9Vi1i95esohXCF3wuKOE8c"", ""'CONSOLIDADO'!G5:AB""), 18, 0), ""-""), """" )"),"PCR – 40T") -> PCR – 40T | V15: =IFERROR(__xludf.DUMMYFUNCTION(" IF ( VLOOKUP($G15,IMPORTRANGE(""https://docs.google.com/spreadsheets/d/1Gpl6jkTg7sL4VDNimUm3S9Vi1i95esohXCF3wuKOE8c"", ""'CONSOLIDADO'!G5:AB""), 10, 0) <> 0, IFERROR(VLOOKUP($G15,IMPORTRANGE(""https://docs.google.com/spreadsheets/d/1Gpl6jkTg7sL4VDNimUm3"&"S9Vi1i95esohXCF3wuKOE8c"", ""'CONSOLIDADO'!G5:AB""), 19, 0), ""-""), """" )"),"https://balanzasprecisur.com/balanzas-comerciales/balanza-torrey-pcr-40t-de-40-kilos/") -> https://balanzasprecisur.com/balanzas-comerciales/balanza-torrey-pcr-40t-de-40-kilos/ | W15: =IFERROR(__xludf.DUMMYFUNCTION("IFERROR(VLOOKUP(G15,IMPORTRANGE(""https://docs.google.com/spreadsheets/d/12RxCea4e5ggM7QGn1XE3FbLQa_-QbCNdBi90OdPjRqg"", ""'Plan de Compras'!D4:Q""), 12, 0), ""NO ESTÁ EN REQ"")"),"Técnica") -> Técnica | X15: =IFERROR(__xludf.DUMMYFUNCTION("IFERROR(VLOOKUP(G15,IMPORTRANGE(""https://docs.google.com/spreadsheets/d/12RxCea4e5ggM7QGn1XE3FbLQa_-QbCNdBi90OdPjRqg"", ""'Plan de Compras'!D4:Q""), 13, 0), """")"),"NACIONAL") -> NACIONAL | Y15: =IFERROR(__xludf.DUMMYFUNCTION("IFERROR(VLOOKUP(G15,IMPORTRANGE(""https://docs.google.com/spreadsheets/d/12RxCea4e5ggM7QGn1XE3FbLQa_-QbCNdBi90OdPjRqg"", ""'Plan de Compras'!D4:Q""), 14, 0), """")"),"ANGIE") -> ANGIE | Z15: =IFERROR(__xludf.DUMMYFUNCTION("IFERROR(VLOOKUP(G15,IMPORTRANGE(""https://docs.google.com/spreadsheets/d/12RxCea4e5ggM7QGn1XE3FbLQa_-QbCNdBi90OdPjRqg"", ""'Plan de Compras'!D4:Q""), 4, 0), """")"),"BALANZA DIGITAL") -> BALANZA DIGITAL | AA15: =IF(H15=Z15,"TRUE", "FALSE") -> TRUE | AB15: =IFERROR(__xludf.DUMMYFUNCTION("IFERROR(IF(OR(C15=TRUE,C15=""""),VLOOKUP(G15,IMPORTRANGE(""https://docs.google.com/spreadsheets/d/1z9A1Wq-kKrhRNG5RS2a2fKpY1wIhSVz2ZNmP2mOl588/edit?usp=sharing"",""REQ VF!E4:H""),4,0),""NO APLICA""),""GENERAR REQ"")"),"GENERAR REQ") -> GENERAR REQ | AC15: =IFERROR(__xludf.DUMMYFUNCTION("IFERROR(QUERY(IMPORTRANGE(""https://docs.google.com/spreadsheets/d/1z9A1Wq-kKrhRNG5RS2a2fKpY1wIhSVz2ZNmP2mOl588/edit?usp=sharing"",""REQ VF!E4:Q""),""SELECT Col10, Col11, Col12 WHERE Col1 = '""&G15&""'"",0),""NO APLICA"")"),"NO APLICA") -> NO APLICA | AF15: C
C16: TRUE | D16: ACCESORIO | E16: EQUIPOS | F16: COM-110 | G16: COM-110-Y.1 | H16: BALANZA DIGITAL | I16: =$I$15 -> 8 | J16: =IFERROR(__xludf.DUMMYFUNCTION("VLOOKUP(G16,IMPORTRANGE(""https://docs.google.com/spreadsheets/d/12RxCea4e5ggM7QGn1XE3FbLQa_-QbCNdBi90OdPjRqg/edit?gid=1692403370#gid=1692403370"", ""'Plan de Compras'!D4:2432""), 8,0)"),8.0) -> 8 | K16: =IF( C16=TRUE, IF(I16=J16,"SI","NO"), "-") -> SI | N16: CON PROVEEDOR EXTERNO | P16: 360 x 435 x 365 mm | S16: TRUE | T16: GENERICO | U16: FUNDAS IMPERMEABLES 48 CM X 42 CM X 40 CM PARA BALANZA DIGITAL | W16: =IFERROR(__xludf.DUMMYFUNCTION("IFERROR(VLOOKUP(G16,IMPORTRANGE(""https://docs.google.com/spreadsheets/d/12RxCea4e5ggM7QGn1XE3FbLQa_-QbCNdBi90OdPjRqg"", ""'Plan de Compras'!D4:Q""), 12, 0), ""NO ESTÁ EN REQ"")"),"Simple") -> Simple | X16: =IFERROR(__xludf.DUMMYFUNCTION("IFERROR(VLOOKUP(G16,IMPORTRANGE(""https://docs.google.com/spreadsheets/d/12RxCea4e5ggM7QGn1XE3FbLQa_-QbCNdBi90OdPjRqg"", ""'Plan de Compras'!D4:Q""), 13, 0), """")"),"NACIONAL") -> NACIONAL | Y16: =IFERROR(__xludf.DUMMYFUNCTION("IFERROR(VLOOKUP(G16,IMPORTRANGE(""https://docs.google.com/spreadsheets/d/12RxCea4e5ggM7QGn1XE3FbLQa_-QbCNdBi90OdPjRqg"", ""'Plan de Compras'!D4:Q""), 14, 0), """")"),"ANGIE") -> ANGIE | Z16: =IFERROR(__xludf.DUMMYFUNCTION("IFERROR(VLOOKUP(G16,IMPORTRANGE(""https://docs.google.com/spreadsheets/d/12RxCea4e5ggM7QGn1XE3FbLQa_-QbCNdBi90OdPjRqg"", ""'Plan de Compras'!D4:Q""), 4, 0), """")"),"FUNDA IMPERMEABLE (1 UND)") -> FUNDA IMPERMEABLE (1 UND) | AA16: =IF(H16=Z16,"TRUE", "FALSE") -> FALSE | AB16: =IFERROR(__xludf.DUMMYFUNCTION("IFERROR(IF(OR(C16=TRUE,C16=""""),VLOOKUP(G16,IMPORTRANGE(""https://docs.google.com/spreadsheets/d/1z9A1Wq-kKrhRNG5RS2a2fKpY1wIhSVz2ZNmP2mOl588/edit?usp=sharing"",""REQ VF!E4:H""),4,0),""NO APLICA""),""GENERAR REQ"")"),"GENERAR REQ") -> GENERAR REQ | AC16: =IFERROR(__xludf.DUMMYFUNCTION("IFERROR(QUERY(IMPORTRANGE(""https://docs.google.com/spreadsheets/d/1z9A1Wq-kKrhRNG5RS2a2fKpY1wIhSVz2ZNmP2mOl588/edit?usp=sharing"",""REQ VF!E4:Q""),""SELECT Col10, Col11, Col12 WHERE Col1 = '""&G16&""'"",0),""NO APLICA"")"),"NO APLICA") -> NO APLICA
A17: 6 | B17: TRUE | C17: TRUE | D17: BIEN | E17: EQUIPOS | F17: COM-111 | G17: COM-111 | H17: BALANZA GRAMERA 500G | I17: =SUMIFS('Hoja 10'!$O:$O,'Hoja 10'!$F:$F,$G17) -> 4 | J17: =IFERROR(__xludf.DUMMYFUNCTION("VLOOKUP(G17,IMPORTRANGE(""https://docs.google.com/spreadsheets/d/12RxCea4e5ggM7QGn1XE3FbLQa_-QbCNdBi90OdPjRqg/edit?gid=1692403370#gid=1692403370"", ""'Plan de Compras'!D4:2432""), 8,0)"),4.0) -> 4 | K17: =IF( C17=TRUE, IF(I17=J17,"SI","NO"), "-") -> SI | L17: INDUSTRIA ALIMENTARIA | M17: 12 Taller_Industria_Alimentaria_Firmado.pdf | O17: =VLOOKUP($G17,'Hoja 10'!$F$4:$AA478, 19,0) -> Truper | P17: =VLOOKUP($G17,'Hoja 10'!$F$4:$AA478, 20,0) -> Báscula electrónica de precisión, de bolsillo, 500 g | Q17: =VLOOKUP($G17,'Hoja 10'!$F$4:$AA478, 21,0) -> https://www.truper.com/ficha_tecnica/Bascula-digital-de-precision-de-bolsillo-500g-Truper.html?code=102316 | R17: COM-111 BALANZA GRAMERA 500G - CET | S17: TRUE | T17: =IFERROR(__xludf.DUMMYFUNCTION(" IF ( VLOOKUP($G17,IMPORTRANGE(""https://docs.google.com/spreadsheets/d/1Gpl6jkTg7sL4VDNimUm3S9Vi1i95esohXCF3wuKOE8c"", ""'CONSOLIDADO'!G5:AB""), 10, 0) <> 0, IFERROR(VLOOKUP($G17,IMPORTRANGE(""https://docs.google.com/spreadsheets/d/1Gpl6jkTg7sL4VDNimUm3"&"S9Vi1i95esohXCF3wuKOE8c"", ""'CONSOLIDADO'!G5:AB""), 17, 0), ""-""), """" )"),"TRUPER ") -> TRUPER | U17: =IFERROR(__xludf.DUMMYFUNCTION(" IF ( VLOOKUP($G17,IMPORTRANGE(""https://docs.google.com/spreadsheets/d/1Gpl6jkTg7sL4VDNimUm3S9Vi1i95esohXCF3wuKOE8c"", ""'CONSOLIDADO'!G5:AB""), 10, 0) <> 0, IFERROR(VLOOKUP($G17,IMPORTRANGE(""https://docs.google.com/spreadsheets/d/1Gpl6jkTg7sL4VDNimUm3"&"S9Vi1i95esohXCF3wuKOE8c"", ""'CONSOLIDADO'!G5:AB""), 18, 0), ""-""), """" )"),"BASE-05B") -> BASE-05B | V17: =IFERROR(__xludf.DUMMYFUNCTION(" IF ( VLOOKUP($G17,IMPORTRANGE(""https://docs.google.com/spreadsheets/d/1Gpl6jkTg7sL4VDNimUm3S9Vi1i95esohXCF3wuKOE8c"", ""'CONSOLIDADO'!G5:AB""), 10, 0) <> 0, IFERROR(VLOOKUP($G17,IMPORTRANGE(""https://docs.google.com/spreadsheets/d/1Gpl6jkTg7sL4VDNimUm3"&"S9Vi1i95esohXCF3wuKOE8c"", ""'CONSOLIDADO'!G5:AB""), 19, 0), ""-""), """" )"),"https://www.truper.com/ficha_tecnica/Bascula-digital-de-precision-de-bolsillo-500g-Truper.html?code=102316") -> https://www.truper.com/ficha_tecnica/Bascula-digital-de-precision-de-bolsillo-500g-Truper.html?code=102316 | W17: =IFERROR(__xludf.DUMMYFUNCTION("IFERROR(VLOOKUP(G17,IMPORTRANGE(""https://docs.google.com/spreadsheets/d/12RxCea4e5ggM7QGn1XE3FbLQa_-QbCNdBi90OdPjRqg"", ""'Plan de Compras'!D4:Q""), 12, 0), ""NO ESTÁ EN REQ"")"),"Técnica") -> Técnica | X17: =IFERROR(__xludf.DUMMYFUNCTION("IFERROR(VLOOKUP(G17,IMPORTRANGE(""https://docs.google.com/spreadsheets/d/12RxCea4e5ggM7QGn1XE3FbLQa_-QbCNdBi90OdPjRqg"", ""'Plan de Compras'!D4:Q""), 13, 0), """")"),"NACIONAL") -> NACIONAL | Y17: =IFERROR(__xludf.DUMMYFUNCTION("IFERROR(VLOOKUP(G17,IMPORTRANGE(""https://docs.google.com/spreadsheets/d/12RxCea4e5ggM7QGn1XE3FbLQa_-QbCNdBi90OdPjRqg"", ""'Plan de Compras'!D4:Q""), 14, 0), """")"),"ANGIE") -> ANGIE | Z17: =IFERROR(__xludf.DUMMYFUNCTION("IFERROR(VLOOKUP(G17,IMPORTRANGE(""https://docs.google.com/spreadsheets/d/12RxCea4e5ggM7QGn1XE3FbLQa_-QbCNdBi90OdPjRqg"", ""'Plan de Compras'!D4:Q""), 4, 0), """")"),"BALANZA GRAMERA 500G") -> BALANZA GRAMERA 500G | AA17: =IF(H17=Z17,"TRUE", "FALSE") -> TRUE | AB17: =IFERROR(__xludf.DUMMYFUNCTION("IFERROR(IF(OR(C17=TRUE,C17=""""),VLOOKUP(G17,IMPORTRANGE(""https://docs.google.com/spreadsheets/d/1z9A1Wq-kKrhRNG5RS2a2fKpY1wIhSVz2ZNmP2mOl588/edit?usp=sharing"",""REQ VF!E4:H""),4,0),""NO APLICA""),""GENERAR REQ"")"),"GENERAR REQ") -> GENERAR REQ | AC17: =IFERROR(__xludf.DUMMYFUNCTION("IFERROR(QUERY(IMPORTRANGE(""https://docs.google.com/spreadsheets/d/1z9A1Wq-kKrhRNG5RS2a2fKpY1wIhSVz2ZNmP2mOl588/edit?usp=sharing"",""REQ VF!E4:Q""),""SELECT Col10, Col11, Col12 WHERE Col1 = '""&G17&""'"",0),""NO APLICA"")"),"NO APLICA") -> NO APLICA | AF17: C
A18: 7 | B18: TRUE | C18: FALSE | D18: BIEN | E18: EQUIPOS | F18: COM-123 | G18: COM-123 | H18: CABINA DE SOLDAR CON MESA DE TRABAJO | I18: =SUMIFS('Hoja 10'!$O:$O,'Hoja 10'!$F:$F,$G18) -> 4 | J18: =IFERROR(__xludf.DUMMYFUNCTION("VLOOKUP(G18,IMPORTRANGE(""https://docs.google.com/spreadsheets/d/12RxCea4e5ggM7QGn1XE3FbLQa_-QbCNdBi90OdPjRqg/edit?gid=1692403370#gid=1692403370"", ""'Plan de Compras'!D4:2432""), 8,0)"),"#N/A") -> #N/A | K18: =IF( C18=TRUE, IF(I18=J18,"SI","NO"), "-") -> - | L18: CONSTRUCCIONES METÁLICAS | M18: 16 Taller_Construcciones Metálicas_Firmado.pdf | N18: SE MANDA A FABRICAR | O18: =VLOOKUP($G18,'Hoja 10'!$F$4:$AA478, 19,0) -> NUPRINOX | P18: =VLOOKUP($G18,'Hoja 10'!$F$4:$AA478, 20,0) -> A medida | Q18: =VLOOKUP($G18,'Hoja 10'!$F$4:$AA478, 21,0) -> https://www.amazon.com/-/es/soldadura-pulgadas-industrial-capacidad-port%C3%A1til/dp/B0DDPVR3L1 | R18: COM-123 CABINA DE SOLDAR CON MESA DE TRABAJO - CET | S18: TRUE | T18: =IFERROR(__xludf.DUMMYFUNCTION(" IF ( VLOOKUP($G18,IMPORTRANGE(""https://docs.google.com/spreadsheets/d/1Gpl6jkTg7sL4VDNimUm3S9Vi1i95esohXCF3wuKOE8c"", ""'CONSOLIDADO'!G5:AB""), 10, 0) <> 0, IFERROR(VLOOKUP($G18,IMPORTRANGE(""https://docs.google.com/spreadsheets/d/1Gpl6jkTg7sL4VDNimUm3"&"S9Vi1i95esohXCF3wuKOE8c"", ""'CONSOLIDADO'!G5:AB""), 17, 0), ""-""), """" )"),"A MEDIDA HUGO") -> A MEDIDA HUGO | U18: =IFERROR(__xludf.DUMMYFUNCTION(" IF ( VLOOKUP($G18,IMPORTRANGE(""https://docs.google.com/spreadsheets/d/1Gpl6jkTg7sL4VDNimUm3S9Vi1i95esohXCF3wuKOE8c"", ""'CONSOLIDADO'!G5:AB""), 10, 0) <> 0, IFERROR(VLOOKUP($G18,IMPORTRANGE(""https://docs.google.com/spreadsheets/d/1Gpl6jkTg7sL4VDNimUm3"&"S9Vi1i95esohXCF3wuKOE8c"", ""'CONSOLIDADO'!G5:AB""), 18, 0), ""-""), """" )"),"A MEDIDA") -> A MEDIDA | V18: =IFERROR(__xludf.DUMMYFUNCTION(" IF ( VLOOKUP($G18,IMPORTRANGE(""https://docs.google.com/spreadsheets/d/1Gpl6jkTg7sL4VDNimUm3S9Vi1i95esohXCF3wuKOE8c"", ""'CONSOLIDADO'!G5:AB""), 10, 0) <> 0, IFERROR(VLOOKUP($G18,IMPORTRANGE(""https://docs.google.com/spreadsheets/d/1Gpl6jkTg7sL4VDNimUm3"&"S9Vi1i95esohXCF3wuKOE8c"", ""'CONSOLIDADO'!G5:AB""), 19, 0), ""-""), """" )"),"") | W18: =IFERROR(__xludf.DUMMYFUNCTION("IFERROR(VLOOKUP(G18,IMPORTRANGE(""https://docs.google.com/spreadsheets/d/12RxCea4e5ggM7QGn1XE3FbLQa_-QbCNdBi90OdPjRqg"", ""'Plan de Compras'!D4:Q""), 12, 0), ""NO ESTÁ EN REQ"")"),"NO ESTÁ EN REQ") -> NO ESTÁ EN REQ | X18: =IFERROR(__xludf.DUMMYFUNCTION("IFERROR(VLOOKUP(G18,IMPORTRANGE(""https://docs.google.com/spreadsheets/d/12RxCea4e5ggM7QGn1XE3FbLQa_-QbCNdBi90OdPjRqg"", ""'Plan de Compras'!D4:Q""), 13, 0), """")"),"") | Y18: =IFERROR(__xludf.DUMMYFUNCTION("IFERROR(VLOOKUP(G18,IMPORTRANGE(""https://docs.google.com/spreadsheets/d/12RxCea4e5ggM7QGn1XE3FbLQa_-QbCNdBi90OdPjRqg"", ""'Plan de Compras'!D4:Q""), 14, 0), """")"),"") | Z18: =IFERROR(__xludf.DUMMYFUNCTION("IFERROR(VLOOKUP(G18,IMPORTRANGE(""https://docs.google.com/spreadsheets/d/12RxCea4e5ggM7QGn1XE3FbLQa_-QbCNdBi90OdPjRqg"", ""'Plan de Compras'!D4:Q""), 4, 0), """")"),"") | AB18: =IFERROR(__xludf.DUMMYFUNCTION("IFERROR(IF(OR(C18=TRUE,C18=""""),VLOOKUP(G18,IMPORTRANGE(""https://docs.google.com/spreadsheets/d/1z9A1Wq-kKrhRNG5RS2a2fKpY1wIhSVz2ZNmP2mOl588/edit?usp=sharing"",""REQ VF!E4:H""),4,0),""NO APLICA""),""GENERAR REQ"")"),"NO APLICA") -> NO APLICA | AC18: =IFERROR(__xludf.DUMMYFUNCTION("IFERROR(QUERY(IMPORTRANGE(""https://docs.google.com/spreadsheets/d/1z9A1Wq-kKrhRNG5RS2a2fKpY1wIhSVz2ZNmP2mOl588/edit?usp=sharing"",""REQ VF!E4:Q""),""SELECT Col10, Col11, Col12 WHERE Col1 = '""&G18&""'"",0),""NO APLICA"")"),"NO APLICA") -> NO APLICA
C19: TRUE | D19: COMPONENTE | E19: EQUIPOS | F19: COM-123 | G19: COM-123.1 | H19: CABINA DE SOLDAR 2.20 X 0.90 X 0.90 M (1 UND) | I19: =$I$18 -> 4 | J19: =IFERROR(__xludf.DUMMYFUNCTION("VLOOKUP(G19,IMPORTRANGE(""https://docs.google.com/spreadsheets/d/12RxCea4e5ggM7QGn1XE3FbLQa_-QbCNdBi90OdPjRqg/edit?gid=1692403370#gid=1692403370"", ""'Plan de Compras'!D4:2432""), 8,0)"),4.0) -> 4 | K19: =IF( C19=TRUE, IF(I19=J19,"SI","NO"), "-") -> SI | S19: TRUE | T19: HUGO | U19: A MEDIDA | W19: =IFERROR(__xludf.DUMMYFUNCTION("IFERROR(VLOOKUP(G19,IMPORTRANGE(""https://docs.google.com/spreadsheets/d/12RxCea4e5ggM7QGn1XE3FbLQa_-QbCNdBi90OdPjRqg"", ""'Plan de Compras'!D4:Q""), 12, 0), ""NO ESTÁ EN REQ"")"),"Técnica") -> Técnica | X19: =IFERROR(__xludf.DUMMYFUNCTION("IFERROR(VLOOKUP(G19,IMPORTRANGE(""https://docs.google.com/spreadsheets/d/12RxCea4e5ggM7QGn1XE3FbLQa_-QbCNdBi90OdPjRqg"", ""'Plan de Compras'!D4:Q""), 13, 0), """")"),"NACIONAL") -> NACIONAL | Y19: =IFERROR(__xludf.DUMMYFUNCTION("IFERROR(VLOOKUP(G19,IMPORTRANGE(""https://docs.google.com/spreadsheets/d/12RxCea4e5ggM7QGn1XE3FbLQa_-QbCNdBi90OdPjRqg"", ""'Plan de Compras'!D4:Q""), 14, 0), """")"),"OMAR") -> OMAR | Z19: =IFERROR(__xludf.DUMMYFUNCTION("IFERROR(VLOOKUP(G19,IMPORTRANGE(""https://docs.google.com/spreadsheets/d/12RxCea4e5ggM7QGn1XE3FbLQa_-QbCNdBi90OdPjRqg"", ""'Plan de Compras'!D4:Q""), 4, 0), """")"),"CABINA DE SOLDAR 2.20 X 0.90 X 0.90 M (1 UND)") -> CABINA DE SOLDAR 2.20 X 0.90 X 0.90 M (1 UND) | AA19: =IF(H19=Z19,"TRUE", "FALSE") -> TRUE | AB19: =IFERROR(__xludf.DUMMYFUNCTION("IFERROR(IF(OR(C19=TRUE,C19=""""),VLOOKUP(G19,IMPORTRANGE(""https://docs.google.com/spreadsheets/d/1z9A1Wq-kKrhRNG5RS2a2fKpY1wIhSVz2ZNmP2mOl588/edit?usp=sharing"",""REQ VF!E4:H""),4,0),""NO APLICA""),""GENERAR REQ"")"),"GENERAR REQ") -> GENERAR REQ | AC19: =IFERROR(__xludf.DUMMYFUNCTION("IFERROR(QUERY(IMPORTRANGE(""https://docs.google.com/spreadsheets/d/1z9A1Wq-kKrhRNG5RS2a2fKpY1wIhSVz2ZNmP2mOl588/edit?usp=sharing"",""REQ VF!E4:Q""),""SELECT Col10, Col11, Col12 WHERE Col1 = '""&G19&""'"",0),""NO APLICA"")"),"NO APLICA") -> NO APLICA
C20: TRUE | D20: COMPONENTE | E20: EQUIPOS | F20: COM-123 | G20: COM-123.2 | H20: MESA DE SOLDADURA MÓVIL 0.80 X 0.60 X 0.75 M (1 UND) | I20: =$I$18 -> 4 | J20: =IFERROR(__xludf.DUMMYFUNCTION("VLOOKUP(G20,IMPORTRANGE(""https://docs.google.com/spreadsheets/d/12RxCea4e5ggM7QGn1XE3FbLQa_-QbCNdBi90OdPjRqg/edit?gid=1692403370#gid=1692403370"", ""'Plan de Compras'!D4:2432""), 8,0)"),4.0) -> 4 | K20: =IF( C20=TRUE, IF(I20=J20,"SI","NO"), "-") -> SI | N20: SE MANDA A FABRICAR | S20: TRUE | T20: HUGO | U20: A MEDIDA | W20: =IFERROR(__xludf.DUMMYFUNCTION("IFERROR(VLOOKUP(G20,IMPORTRANGE(""https://docs.google.com/spreadsheets/d/12RxCea4e5ggM7QGn1XE3FbLQa_-QbCNdBi90OdPjRqg"", ""'Plan de Compras'!D4:Q""), 12, 0), ""NO ESTÁ EN REQ"")"),"Técnica") -> Técnica | X20: =IFERROR(__xludf.DUMMYFUNCTION("IFERROR(VLOOKUP(G20,IMPORTRANGE(""https://docs.google.com/spreadsheets/d/12RxCea4e5ggM7QGn1XE3FbLQa_-QbCNdBi90OdPjRqg"", ""'Plan de Compras'!D4:Q""), 13, 0), """")"),"NACIONAL") -> NACIONAL | Y20: =IFERROR(__xludf.DUMMYFUNCTION("IFERROR(VLOOKUP(G20,IMPORTRANGE(""https://docs.google.com/spreadsheets/d/12RxCea4e5ggM7QGn1XE3FbLQa_-QbCNdBi90OdPjRqg"", ""'Plan de Compras'!D4:Q""), 14, 0), """")"),"OMAR") -> OMAR | Z20: =IFERROR(__xludf.DUMMYFUNCTION("IFERROR(VLOOKUP(G20,IMPORTRANGE(""https://docs.google.com/spreadsheets/d/12RxCea4e5ggM7QGn1XE3FbLQa_-QbCNdBi90OdPjRqg"", ""'Plan de Compras'!D4:Q""), 4, 0), """")"),"MESA DE SOLDADURA MÓVIL 0.80 X 0.60 X 0.75 M (1 UND)") -> MESA DE SOLDADURA MÓVIL 0.80 X 0.60 X 0.75 M (1 UND) | AA20: =IF(H20=Z20,"TRUE", "FALSE") -> TRUE | AB20: =IFERROR(__xludf.DUMMYFUNCTION("IFERROR(IF(OR(C20=TRUE,C20=""""),VLOOKUP(G20,IMPORTRANGE(""https://docs.google.com/spreadsheets/d/1z9A1Wq-kKrhRNG5RS2a2fKpY1wIhSVz2ZNmP2mOl588/edit?usp=sharing"",""REQ VF!E4:H""),4,0),""NO APLICA""),""GENERAR REQ"")"),"GENERAR REQ") -> GENERAR REQ | AC20: =IFERROR(__xludf.DUMMYFUNCTION("IFERROR(QUERY(IMPORTRANGE(""https://docs.google.com/spreadsheets/d/1z9A1Wq-kKrhRNG5RS2a2fKpY1wIhSVz2ZNmP2mOl588/edit?usp=sharing"",""REQ VF!E4:Q""),""SELECT Col10, Col11, Col12 WHERE Col1 = '""&G20&""'"",0),""NO APLICA"")"),"NO APLICA") -> NO APLICA
A21: 8 | B21: TRUE | C21: TRUE | D21: BIEN | E21: EQUIPOS | F21: ESP-103 | G21: ESP-103 | H21: AMOLADORA | I21: =SUMIFS('Hoja 10'!$O:$O,'Hoja 10'!$F:$F,$G21) -> 4 | J21: =IFERROR(__xludf.DUMMYFUNCTION("VLOOKUP(G21,IMPORTRANGE(""https://docs.google.com/spreadsheets/d/12RxCea4e5ggM7QGn1XE3FbLQa_-QbCNdBi90OdPjRqg/edit?gid=1692403370#gid=1692403370"", ""'Plan de Compras'!D4:2432""), 8,0)"),4.0) -> 4 | K21: =IF( C21=TRUE, IF(I21=J21,"SI","NO"), "-") -> SI | L21: MECÁNICA AUTOMOTRÍZ, CONSTRUCCIONES METÁLICAS | M21: 1 Taller_Mecanica_Automotriz_Firmado.pdf | O21: =VLOOKUP($G21,'Hoja 10'!$F$4:$AA478, 19,0) -> BOSCH | P21: =VLOOKUP($G21,'Hoja 10'!$F$4:$AA478, 20,0) -> GWS 9-125 P | Q21: =VLOOKUP($G21,'Hoja 10'!$F$4:$AA478, 21,0) -> https://soelco.co/producto/mini-pulidora-angular-segura-900-w-125-mm-110-v-bosch/?srsltid=AfmBOorerIGp1jcFwSUGxZb2mjq5MenuM3THMVYyN7v09ItDhlwh_pEr | R21: ESP-103 AMOLADORA - CET | S21: TRUE | T21: =IFERROR(__xludf.DUMMYFUNCTION(" IF ( VLOOKUP($G21,IMPORTRANGE(""https://docs.google.com/spreadsheets/d/1Gpl6jkTg7sL4VDNimUm3S9Vi1i95esohXCF3wuKOE8c"", ""'CONSOLIDADO'!G5:AB""), 10, 0) <> 0, IFERROR(VLOOKUP($G21,IMPORTRANGE(""https://docs.google.com/spreadsheets/d/1Gpl6jkTg7sL4VDNimUm3"&"S9Vi1i95esohXCF3wuKOE8c"", ""'CONSOLIDADO'!G5:AB""), 17, 0), ""-""), """" )"),"BOSCH") -> BOSCH | U21: =IFERROR(__xludf.DUMMYFUNCTION(" IF ( VLOOKUP($G21,IMPORTRANGE(""https://docs.google.com/spreadsheets/d/1Gpl6jkTg7sL4VDNimUm3S9Vi1i95esohXCF3wuKOE8c"", ""'CONSOLIDADO'!G5:AB""), 10, 0) <> 0, IFERROR(VLOOKUP($G21,IMPORTRANGE(""https://docs.google.com/spreadsheets/d/1Gpl6jkTg7sL4VDNimUm3"&"S9Vi1i95esohXCF3wuKOE8c"", ""'CONSOLIDADO'!G5:AB""), 18, 0), ""-""), """" )"),"GWS 12-125 P") -> GWS 12-125 P | V21: =IFERROR(__xludf.DUMMYFUNCTION(" IF ( VLOOKUP($G21,IMPORTRANGE(""https://docs.google.com/spreadsheets/d/1Gpl6jkTg7sL4VDNimUm3S9Vi1i95esohXCF3wuKOE8c"", ""'CONSOLIDADO'!G5:AB""), 10, 0) <> 0, IFERROR(VLOOKUP($G21,IMPORTRANGE(""https://docs.google.com/spreadsheets/d/1Gpl6jkTg7sL4VDNimUm3"&"S9Vi1i95esohXCF3wuKOE8c"", ""'CONSOLIDADO'!G5:AB""), 19, 0), ""-""), """" )"),"https://www.bosch-professional.com/pe/es/products/gws-12-125-p-06013A62E0") -> https://www.bosch-professional.com/pe/es/products/gws-12-125-p-06013A62E0 | W21: =IFERROR(__xludf.DUMMYFUNCTION("IFERROR(VLOOKUP(G21,IMPORTRANGE(""https://docs.google.com/spreadsheets/d/12RxCea4e5ggM7QGn1XE3FbLQa_-QbCNdBi90OdPjRqg"", ""'Plan de Compras'!D4:Q""), 12, 0), ""NO ESTÁ EN REQ"")"),"Técnica") -> Técnica | X21: =IFERROR(__xludf.DUMMYFUNCTION("IFERROR(VLOOKUP(G21,IMPORTRANGE(""https://docs.google.com/spreadsheets/d/12RxCea4e5ggM7QGn1XE3FbLQa_-QbCNdBi90OdPjRqg"", ""'Plan de Compras'!D4:Q""), 13, 0), """")"),"NACIONAL") -> NACIONAL | Y21: =IFERROR(__xludf.DUMMYFUNCTION("IFERROR(VLOOKUP(G21,IMPORTRANGE(""https://docs.google.com/spreadsheets/d/12RxCea4e5ggM7QGn1XE3FbLQa_-QbCNdBi90OdPjRqg"", ""'Plan de Compras'!D4:Q""), 14, 0), """")"),"JESSICA") -> JESSICA | Z21: =IFERROR(__xludf.DUMMYFUNCTION("IFERROR(VLOOKUP(G21,IMPORTRANGE(""https://docs.google.com/spreadsheets/d/12RxCea4e5ggM7QGn1XE3FbLQa_-QbCNdBi90OdPjRqg"", ""'Plan de Compras'!D4:Q""), 4, 0), """")"),"AMOLADORA") -> AMOLADORA | AA21: =IF(H21=Z21,"TRUE", "FALSE") -> TRUE | AB21: =IFERROR(__xludf.DUMMYFUNCTION("IFERROR(IF(OR(C21=TRUE,C21=""""),VLOOKUP(G21,IMPORTRANGE(""https://docs.google.com/spreadsheets/d/1z9A1Wq-kKrhRNG5RS2a2fKpY1wIhSVz2ZNmP2mOl588/edit?usp=sharing"",""REQ VF!E4:H""),4,0),""NO APLICA""),""GENERAR REQ"")"),"GENERAR REQ") -> GENERAR REQ | AC21: =IFERROR(__xludf.DUMMYFUNCTION("IFERROR(QUERY(IMPORTRANGE(""https://docs.google.com/spreadsheets/d/1z9A1Wq-kKrhRNG5RS2a2fKpY1wIhSVz2ZNmP2mOl588/edit?usp=sharing"",""REQ VF!E4:Q""),""SELECT Col10, Col11, Col12 WHERE Col1 = '""&G21&""'"",0),""NO APLICA"")"),"NO APLICA") -> NO APLICA | AF21: C
C22: TRUE | D22: ACCESORIO | E22: EQUIPOS | F22: ESP-103 | G22: ESP-103.1 | H22: DISCO DIAMANTADO 125 MM (5 UND) | I22: =$I$21*5 -> 20 | J22: =IFERROR(__xludf.DUMMYFUNCTION("VLOOKUP(G22,IMPORTRANGE(""https://docs.google.com/spreadsheets/d/12RxCea4e5ggM7QGn1XE3FbLQa_-QbCNdBi90OdPjRqg/edit?gid=1692403370#gid=1692403370"", ""'Plan de Compras'!D4:2432""), 8,0)"),20.0) -> 20 | K22: =IF( C22=TRUE, IF(I22=J22,"SI","NO"), "-") -> SI | N22: DISCO DIAMANTADO DE 125 mm | Q22: https://www.maqcenter.pe/product/vaso-diamantado-para-concreto-segmentado-125-x-22-23mm-bosch-2608-601-762 | S22: TRUE | T22: BOSCH | U22: 2608.601.762-000 | V22: https://drive.google.com/file/d/1V2qh049uZB1V53EYh7eIWzBpKuZA9Hec/view?usp=sharing | W22: =IFERROR(__xludf.DUMMYFUNCTION("IFERROR(VLOOKUP(G22,IMPORTRANGE(""https://docs.google.com/spreadsheets/d/12RxCea4e5ggM7QGn1XE3FbLQa_-QbCNdBi90OdPjRqg"", ""'Plan de Compras'!D4:Q""), 12, 0), ""NO ESTÁ EN REQ"")"),"Simple") -> Simple | X22: =IFERROR(__xludf.DUMMYFUNCTION("IFERROR(VLOOKUP(G22,IMPORTRANGE(""https://docs.google.com/spreadsheets/d/12RxCea4e5ggM7QGn1XE3FbLQa_-QbCNdBi90OdPjRqg"", ""'Plan de Compras'!D4:Q""), 13, 0), """")"),"NACIONAL") -> NACIONAL | Y22: =IFERROR(__xludf.DUMMYFUNCTION("IFERROR(VLOOKUP(G22,IMPORTRANGE(""https://docs.google.com/spreadsheets/d/12RxCea4e5ggM7QGn1XE3FbLQa_-QbCNdBi90OdPjRqg"", ""'Plan de Compras'!D4:Q""), 14, 0), """")"),"JESSICA") -> JESSICA | Z22: =IFERROR(__xludf.DUMMYFUNCTION("IFERROR(VLOOKUP(G22,IMPORTRANGE(""https://docs.google.com/spreadsheets/d/12RxCea4e5ggM7QGn1XE3FbLQa_-QbCNdBi90OdPjRqg"", ""'Plan de Compras'!D4:Q""), 4, 0), """")"),"DISCO DIAMANTADO 125 MM (5 UND)") -> DISCO DIAMANTADO 125 MM (5 UND) | AA22: =IF(H22=Z22,"TRUE", "FALSE") -> TRUE | AB22: =IFERROR(__xludf.DUMMYFUNCTION("IFERROR(IF(OR(C22=TRUE,C22=""""),VLOOKUP(G22,IMPORTRANGE(""https://docs.google.com/spreadsheets/d/1z9A1Wq-kKrhRNG5RS2a2fKpY1wIhSVz2ZNmP2mOl588/edit?usp=sharing"",""REQ VF!E4:H""),4,0),""NO APLICA""),""GENERAR REQ"")"),"GENERAR REQ") -> GENERAR REQ | AC22: =IFERROR(__xludf.DUMMYFUNCTION("IFERROR(QUERY(IMPORTRANGE(""https://docs.google.com/spreadsheets/d/1z9A1Wq-kKrhRNG5RS2a2fKpY1wIhSVz2ZNmP2mOl588/edit?usp=sharing"",""REQ VF!E4:Q""),""SELECT Col10, Col11, Col12 WHERE Col1 = '""&G22&""'"",0),""NO APLICA"")"),"NO APLICA") -> NO APLICA
C23: TRUE | D23: ACCESORIO | E23: EQUIPOS | F23: ESP-103 | G23: ESP-103.2 | H23: FUNDA DE POLIAMIDA (1 UND) | I23: 4 | J23: =IFERROR(__xludf.DUMMYFUNCTION("VLOOKUP(G23,IMPORTRANGE(""https://docs.google.com/spreadsheets/d/12RxCea4e5ggM7QGn1XE3FbLQa_-QbCNdBi90OdPjRqg/edit?gid=1692403370#gid=1692403370"", ""'Plan de Compras'!D4:2432""), 8,0)"),4.0) -> 4 | K23: =IF( C23=TRUE, IF(I23=J23,"SI","NO"), "-") -> SI | S23: TRUE | T23: GENERICO | U23: FUNDAS DE POLIAMIDAS 35.2 CM x 31.5 CM x 15.8 CM PARA AMOLADORA | W23: =IFERROR(__xludf.DUMMYFUNCTION("IFERROR(VLOOKUP(G23,IMPORTRANGE(""https://docs.google.com/spreadsheets/d/12RxCea4e5ggM7QGn1XE3FbLQa_-QbCNdBi90OdPjRqg"", ""'Plan de Compras'!D4:Q""), 12, 0), ""NO ESTÁ EN REQ"")"),"Simple") -> Simple | X23: =IFERROR(__xludf.DUMMYFUNCTION("IFERROR(VLOOKUP(G23,IMPORTRANGE(""https://docs.google.com/spreadsheets/d/12RxCea4e5ggM7QGn1XE3FbLQa_-QbCNdBi90OdPjRqg"", ""'Plan de Compras'!D4:Q""), 13, 0), """")"),"NACIONAL") -> NACIONAL | Y23: =IFERROR(__xludf.DUMMYFUNCTION("IFERROR(VLOOKUP(G23,IMPORTRANGE(""https://docs.google.com/spreadsheets/d/12RxCea4e5ggM7QGn1XE3FbLQa_-QbCNdBi90OdPjRqg"", ""'Plan de Compras'!D4:Q""), 14, 0), """")"),"ANGIE") -> ANGIE | Z23: =IFERROR(__xludf.DUMMYFUNCTION("IFERROR(VLOOKUP(G23,IMPORTRANGE(""https://docs.google.com/spreadsheets/d/12RxCea4e5ggM7QGn1XE3FbLQa_-QbCNdBi90OdPjRqg"", ""'Plan de Compras'!D4:Q""), 4, 0), """")"),"FUNDA DE POLIAMIDA (1 UND)") -> FUNDA DE POLIAMIDA (1 UND) | AB23: =IFERROR(__xludf.DUMMYFUNCTION("IFERROR(IF(OR(C23=TRUE,C23=""""),VLOOKUP(G23,IMPORTRANGE(""https://docs.google.com/spreadsheets/d/1z9A1Wq-kKrhRNG5RS2a2fKpY1wIhSVz2ZNmP2mOl588/edit?usp=sharing"",""REQ VF!E4:H""),4,0),""NO APLICA""),""GENERAR REQ"")"),"GENERAR REQ") -> GENERAR REQ | AC23: =IFERROR(__xludf.DUMMYFUNCTION("IFERROR(QUERY(IMPORTRANGE(""https://docs.google.com/spreadsheets/d/1z9A1Wq-kKrhRNG5RS2a2fKpY1wIhSVz2ZNmP2mOl588/edit?usp=sharing"",""REQ VF!E4:Q""),""SELECT Col10, Col11, Col12 WHERE Col1 = '""&G23&""'"",0),""NO APLICA"")"),"NO APLICA") -> NO APLICA
C24: FALSE | D24: ACCESORIO | E24: EQUIPOS | F24: ESP-103 | G24: ESP-103.3 | H24: MANUAL DE INSTRUCCIONES (1 UND) | I24: 0 | J24: =IFERROR(__xludf.DUMMYFUNCTION("VLOOKUP(G24,IMPORTRANGE(""https://docs.google.com/spreadsheets/d/12RxCea4e5ggM7QGn1XE3FbLQa_-QbCNdBi90OdPjRqg/edit?gid=1692403370#gid=1692403370"", ""'Plan de Compras'!D4:2432""), 8,0)"),"#N/A") -> #N/A | K24: =IF( C24=TRUE, IF(I24=J24,"SI","NO"), "-") -> - | S24: TRUE | T24: BOSCH | U24: INCLUÍDO | W24: =IFERROR(__xludf.DUMMYFUNCTION("IFERROR(VLOOKUP(G24,IMPORTRANGE(""https://docs.google.com/spreadsheets/d/12RxCea4e5ggM7QGn1XE3FbLQa_-QbCNdBi90OdPjRqg"", ""'Plan de Compras'!D4:Q""), 12, 0), ""NO ESTÁ EN REQ"")"),"NO ESTÁ EN REQ") -> NO ESTÁ EN REQ | X24: =IFERROR(__xludf.DUMMYFUNCTION("IFERROR(VLOOKUP(G24,IMPORTRANGE(""https://docs.google.com/spreadsheets/d/12RxCea4e5ggM7QGn1XE3FbLQa_-QbCNdBi90OdPjRqg"", ""'Plan de Compras'!D4:Q""), 13, 0), """")"),"") | Y24: =IFERROR(__xludf.DUMMYFUNCTION("IFERROR(VLOOKUP(G24,IMPORTRANGE(""https://docs.google.com/spreadsheets/d/12RxCea4e5ggM7QGn1XE3FbLQa_-QbCNdBi90OdPjRqg"", ""'Plan de Compras'!D4:Q""), 14, 0), """")"),"") | Z24: =IFERROR(__xludf.DUMMYFUNCTION("IFERROR(VLOOKUP(G24,IMPORTRANGE(""https://docs.google.com/spreadsheets/d/12RxCea4e5ggM7QGn1XE3FbLQa_-QbCNdBi90OdPjRqg"", ""'Plan de Compras'!D4:Q""), 4, 0), """")"),"") | AB24: =IFERROR(__xludf.DUMMYFUNCTION("IFERROR(IF(OR(C24=TRUE,C24=""""),VLOOKUP(G24,IMPORTRANGE(""https://docs.google.com/spreadsheets/d/1z9A1Wq-kKrhRNG5RS2a2fKpY1wIhSVz2ZNmP2mOl588/edit?usp=sharing"",""REQ VF!E4:H""),4,0),""NO APLICA""),""GENERAR REQ"")"),"NO APLICA") -> NO APLICA | AC24: =IFERROR(__xludf.DUMMYFUNCTION("IFERROR(QUERY(IMPORTRANGE(""https://docs.google.com/spreadsheets/d/1z9A1Wq-kKrhRNG5RS2a2fKpY1wIhSVz2ZNmP2mOl588/edit?usp=sharing"",""REQ VF!E4:Q""),""SELECT Col10, Col11, Col12 WHERE Col1 = '""&G24&""'"",0),""NO APLICA"")"),"NO APLICA") -> NO APLICA
